<mujoco model="example">
    <!-- set some defaults for units and lighting -->
    <include file="../common/visual.xml"/>
    <include file="../common/skybox.xml"/>
    <include file="../common/materials.xml"/>
    <compiler angle="radian" meshdir="./"/>
    <option gravity="0 0 -9.81"/>
    <option timestep="0.02">
        <flag contact="disable" energy="enable"/>
    </option>
    <!-- import our stl files -->
    <asset>
        <mesh name="base" file="shape_ref_mujoco_low.stl" />
        <mesh name="fins" file="pectoral-fins.stl" />
        <mesh name="tail" file="tail.stl" />
        <texture name="texture" file="pool.jpg"/>
        <material name="pool" texture="texture"/>
<!--        <mesh name="tail" file="down.STL" />-->
    </asset>

    <default>
        <general ctrllimited="true"/>
        <default class="fish">
          <joint type="hinge" limited="false" range="-60 60" damping="2e-5" solreflimit=".1 1" solimplimit="0 .8 .1"/>
        </default>
    </default>

    <!-- define our robot model -->
    <worldbody>
        <geom type="plane" size="2000 1500 0.1" rgba="0 .9 .9 1" pos="0 0 -500" euler="0 0 0"/>
        <geom type="plane" size="2000 1500 0.1" rgba="0 .9 .9 .2" pos="0 0 300" material="pool" euler="0 0 0"/>
        <geom name="target" type="sphere" pos="-1000 .4 .1" size="100" material="target"/>
        <geom name="wall0" type="box" size="10 1500 600" rgba="0 .9 .9 1" pos="2000 0 100" euler="0 0 0"/>
        <geom name="wall1" type="box" size="10 1500 600" rgba="0 .9 .9 1" pos="-2000 0 100" euler="0 0 0"/>
        <geom name="wall2" type="box" size="2000 10 600" rgba="0 .9 .9 1" pos="0 1500 100" euler="0 0 0"/>
        <geom name="wall3" type="box" size="2000 10 600" rgba="0 .9 .9 1" pos="0 -1500 100" euler="0 0 0"/>
        <!-- set up a light pointing down on the robot -->
        <light directional="true" pos="0 0 2" dir="0 0 -1" />
        <!-- add a floor so we don't stare off into the abyss -->
        <geom name="floor" pos="0 0 0" size="1 1 1" type="plane" rgba="1 0.83 0.61 0.5"/>

        <!-- start building our model rgba="1 .647 0 1" -->
        <body name="base" pos="0 0 0" childclass="fish">
            <site name="base" size=".01" rgba="0 0 0 0"/>
            <geom name="body" type="mesh" rgba="1 .4 0 1" mesh="base" pos="0 0 0" zaxis="0 1 0"/>
            <geom name="fins" type="mesh" rgba=".9 0 0 1" mesh="fins" pos="0 0 0" zaxis="0 1 0"/>
            <inertial pos="0 0 0" mass="1.3" diaginertia="1e-3 1e-3 1e-3"/>
            <body name="tail" pos="0 0 0">
                <!-- this joint connects tail to base -->
                <joint name="joint1" type="hinge" range="-0.5 0.5" limited="true" axis="0 0 1" pos="200 0 0" damping="1e-9" />
    <!--            <joint name="joint1" type="hinge" axis="0 0 1" pos="200 0 0" damping="1e-6" range="-0.5 0.5"/>-->
                <geom name="tail" type="mesh" rgba="0 0.9 0 1" mesh="tail" pos="0 0 0" zaxis="0 1 0"/>
                <inertial pos="0 0 0" mass="0.075" diaginertia="1e-9 1e-9 1e-9"/>
            </body>
        </body>

    </worldbody>

    <!-- attach actuators to joints -->
    <actuator>
<!--        <position name="dc_motor" joint="joint1" ctrlrange="-1 1" ctrllimited="true" kp="500"/>-->
<!--        <velocity name="velocity_servo" joint="joint1" ctrlrange="-1 1" ctrllimited="true" kv="100"/>-->

<!--        <position name="dc_motor" joint="joint1" ctrlrange="-1 1" ctrllimited="true" kp="5e-2"/>-->
        <motor name="dc_motor" joint="joint1" gear="5000" ctrlrange="-1 1" ctrllimited="true"/>
<!--        <motor name="dc_motor" joint="joint1" gear="0.1" ctrlrange="-0.5 0.5" ctrllimited="true"/>-->
    </actuator>

</mujoco>